<?xml version="1.0"?>
<robot name="qpbot" xmlns:xacro="http://www.ros.org/wiki/xacro">

    <xacro:macro name="create_base" params="parent_link:=base_footprint xyz_offset:='0 0 0' rpy_offset:='0 0 0'">

        <!-- base joint-->
        <joint name="base_joint" type="fixed">
            <parent link="${parent_link}"/>
            <child link="base_link"/>
            <origin xyz="${xyz_offset}" rpy="${rpy_offset}"/>
        </joint>

        <!-- base link-->
        <link name="base_link">
            <visual>
                <origin xyz="0 0 0" rpy="0 0 0"/>
                <geometry>
                    <cylinder length="0.12" radius="0.10"/>
                </geometry>
                <material name="blue">
                    <color rgba="0.1 0.1 1.0 0.5" />
                </material>
            </visual>
            <collision>
                <origin xyz="0 0 0" rpy="0 0 0"/>
                <geometry>
                    <cylinder length="0.12" radius="0.10"/>
                </geometry>
                <material name="blue">
                    <color rgba="0.1 0.1 1.0 0.5" />
                </material>
            </collision>
            <inertial>
                <mass value="0.2"/>
                <inertia ixx="0.0122666" ixy="0" ixz="0" iyy="0.0122666" iyz="0" izz="0.02"/>
            </inertial>
        </link>
    </xacro:macro>

    <xacro:macro name="create_wheel" params="parent_link:=base_link prefix xyz_offset:='0 0 0' rpy_offset='0 0 0' axix=:'0 1 0'">
        
        <!-- wheel joint -->
        <joint name="${prefix}_wheel_joint" type="continuous">
            <parent link="${parent_link}"/>
            <child link="${prefix}_wheel_link"/>
            <origin xyz="${xyz_offset}"/>
            <axis xyz="${axix}"/>
        </joint>

        <!-- wheel link -->
        <link name="${prefix}_wheel_link">
            <visual>
                <origin xyz="0 0 0" rpy="1.57079 0 0"/>
                <geometry>
                    <cylinder length="0.04" radius="0.032"/>
                </geometry>
                <material name="black">
                    <color rgba="0.0 0.0 0.0 0.5" /> 
                </material>
            </visual>
            <collision>
                <origin xyz="0 0 0" rpy="1.57079 0 0"/>
                <geometry>
                    <cylinder length="0.04" radius="0.032"/>
                </geometry>
                <material name="black">
                    <color rgba="0.0 0.0 0.0 0.5" /> 
                </material>
            </collision>
            <inertial>
                <mass value="0.2"/>
                <inertia ixx="0.000190416666667" ixy="0" ixz="0" iyy="0.0001904" iyz="0" izz="0.00036"/>
            </inertial>
        </link>
    </xacro:macro>

    <xacro:macro name="create_caster" params="parent_link:=base_link xyz_offset:='0 0 0' rpy_offset:='0 0 0' axix=:'0 1 0'">
    
        <!-- caster joint-->
        <joint name="caster_joint" type="fixed">
            <parent link="${parent_link}"/>
            <child link="caster_link"/>
            <origin xyz="${xyz_offset}" rpy="${rpy_offset}"/>
        </joint>

        <!-- caster link-->
        <link name="caster_link">
            <visual>
                <origin xyz="0 0 0" rpy="0 1.57079 0"/>
                <geometry>
                    <sphere radius="0.016"/>
                </geometry>
                <material name="black">
                    <color rgba="0.0 0.0 0.0 0.5" /> 
                </material>
            </visual>
            <collision>
                <origin xyz="0 0 0" rpy="1.57079 0 0"/>
                <geometry>
                    <sphere radius="0.016"/>
                </geometry>
                <material name="black">
                    <color rgba="0.0 0.0 0.0 0.5" /> 
                </material>
            </collision>
            <inertial>
                <mass value="0.2"/>
                <inertia ixx="0.000190416666667" ixy="0" ixz="0" iyy="0.0001904" iyz="0" izz="0.00036"/>
            </inertial>
        </link>
    </xacro:macro>

</robot>